<!-- default world exported from ignitiongazebo -->
<!-- model only thing applied over it -->

<sdf version='1.9'>
    <world name='car_world'>
        <physics name='1ms' type='ignored'>
            <max_step_size>0.001</max_step_size>
            <real_time_factor>1</real_time_factor>
            <real_time_update_rate>1000</real_time_update_rate>
        </physics>
        <plugin name='gz::sim::systems::Physics' filename='ignition-gazebo-physics-system' />
        <plugin name='gz::sim::systems::UserCommands'
            filename='ignition-gazebo-user-commands-system' />
        <plugin name='gz::sim::systems::SceneBroadcaster'
            filename='ignition-gazebo-scene-broadcaster-system' />
        <plugin name='gz::sim::systems::Contact' filename='ignition-gazebo-contact-system' />
        <gravity>0 0 -9.8</gravity>
        <magnetic_field>6e-06 2.3e-05 -4.2e-05</magnetic_field>
        <atmosphere type='adiabatic' />
        <scene>
            <ambient>0.4 0.4 0.4 1</ambient>
            <background>0.7 0.7 0.7 1</background>
            <shadows>true</shadows>
        </scene>
        <model name='ground_plane'>
            <static>true</static>
            <link name='link'>
                <collision name='collision'>
                    <geometry>
                        <plane>
                            <normal>0 0 1</normal>
                            <size>100 100</size>
                        </plane>
                    </geometry>
                    <surface>
                        <friction>
                            <ode />
                        </friction>
                        <bounce />
                        <contact />
                    </surface>
                </collision>
                <visual name='visual'>
                    <geometry>
                        <plane>
                            <normal>0 0 1</normal>
                            <size>100 100</size>
                        </plane>
                    </geometry>
                    <material>
                        <ambient>0.8 0.8 0.8 1</ambient>
                        <diffuse>0.8 0.8 0.8 1</diffuse>
                        <specular>0.8 0.8 0.8 1</specular>
                    </material>
                </visual>
                <pose>0 0 0 0 -0 0</pose>
                <inertial>
                    <pose>0 0 0 0 -0 0</pose>
                    <mass>1</mass>
                    <inertia>
                        <ixx>1</ixx>
                        <ixy>0</ixy>
                        <ixz>0</ixz>
                        <iyy>1</iyy>
                        <iyz>0</iyz>
                        <izz>1</izz>
                    </inertia>
                </inertial>
                <enable_wind>false</enable_wind>
            </link>
            <pose>0 0 0 0 -0 0</pose>
            <self_collide>false</self_collide>
        </model>
        <light name='sun' type='directional'>
            <pose>0 0 10 0 -0 0</pose>
            <cast_shadows>true</cast_shadows>
            <intensity>1</intensity>
            <direction>-0.5 0.1 -0.9</direction>
            <diffuse>0.8 0.8 0.8 1</diffuse>
            <specular>0.2 0.2 0.2 1</specular>
            <attenuation>
                <range>1000</range>
                <linear>0.01</linear>
                <constant>0.90000000000000002</constant>
                <quadratic>0.001</quadratic>
            </attenuation>
            <spot>
                <inner_angle>0</inner_angle>
                <outer_angle>0</outer_angle>
                <falloff>0</falloff>
            </spot>
        </light>


        <!-- default export ends here -->
        <model name="vehicle_one" canonical_link='chassis'>
            <pose relative_to='world'>0 0 0 0 0 0</pose>
            <link name='chassis'>
                <pose relative_to='__model__'>0.5 0 0.4 0 0 0</pose>
                <inertial>
                    <mass>1.2</mass>
                    <inertia>
                        <ixx>0.095329</ixx>
                        <ixy>0</ixy>
                        <ixz>0</ixz>
                        <iyy>0.381317</iyy>
                        <iyz>0</iyz>
                        <izz>0.476646</izz>
                    </inertia>
                </inertial>
                <visual name='visual'>
                    <geometry>
                        <box>
                            <size>2.0 1.0 0.5</size>
                        </box>
                    </geometry>
                    <material>
                        <ambient>0.8 0.0 1.0 1</ambient>
                        <diffuse>0.2 0.0 1.0 1</diffuse>
                        <specular>0.0 0.0 1.0 1</specular>
                    </material>
                </visual>
                <collision name='collision'>
                    <geometry>
                        <box>
                            <size>2.0 1.0 0.5</size>
                        </box>
                    </geometry>
                </collision>
            </link>


            <!-- wheels -->

            <link name='left_front_wheel'>
                <pose relative_to="chassis">-0.88 0.6 0 -1.5707 0 0</pose>
                <inertial>
                    <mass>1</mass>
                    <inertia>
                        <ixx>0.043333</ixx>
                        <ixy>0</ixy>
                        <ixz>0</ixz>
                        <iyy>0.043333</iyy>
                        <iyz>0</iyz>
                        <izz>0.08</izz>
                    </inertia>
                </inertial>
                <visual name='visual'>
                    <geometry>
                        <cylinder>
                            <radius>0.4</radius>
                            <length>0.2</length>
                        </cylinder>
                    </geometry>
                    <material>
                        <ambient>0.1 0.1 0.1 1</ambient>
                        <diffuse>0.1 0.1 0.1 1</diffuse>
                        <specular>0.1 0.1 0.1 1</specular>
                    </material>
                    <collision name='collision'>
                        <geometry>
                            <cylinder>
                                <radius>0.4</radius>
                                <length>0.2</length>
                            </cylinder>
                        </geometry>
                    </collision>
                </visual>
            </link>
            <link name='left_rear_wheel'>
                <pose relative_to="chassis">0.88 0.6 0 -1.5707 0 0</pose>
                <inertial>
                    <mass>1</mass>
                    <inertia>
                        <ixx>0.043333</ixx>
                        <ixy>0</ixy>
                        <ixz>0</ixz>
                        <iyy>0.043333</iyy>
                        <iyz>0</iyz>
                        <izz>0.08</izz>
                    </inertia>
                </inertial>
                <visual name='visual'>
                    <geometry>
                        <cylinder>
                            <radius>0.4</radius>
                            <length>0.2</length>
                        </cylinder>
                    </geometry>
                    <material>
                        <ambient>0.1 0.1 0.1 1</ambient>
                        <diffuse>0.1 0.1 0.1 1</diffuse>
                        <specular>0.1 0.1 0.1 1</specular>
                    </material>
                    <collision name='collision'>
                        <geometry>
                            <cylinder>
                                <radius>0.4</radius>
                                <length>0.2</length>
                            </cylinder>
                        </geometry>
                    </collision>
                </visual>
            </link>
            <link name='right_front_wheel'>
                <pose relative_to="chassis">-0.88 -0.6 0 -1.5707 0 0</pose>
                <inertial>
                    <mass>1</mass>
                    <inertia>
                        <ixx>0.043333</ixx>
                        <ixy>0</ixy>
                        <ixz>0</ixz>
                        <iyy>0.043333</iyy>
                        <iyz>0</iyz>
                        <izz>0.08</izz>
                    </inertia>
                </inertial>
                <visual name='visual'>
                    <geometry>
                        <cylinder>
                            <radius>0.4</radius>
                            <length>0.2</length>
                        </cylinder>
                    </geometry>
                    <material>
                        <ambient>0.1 0.1 0.1 1</ambient>
                        <diffuse>0.1 0.1 0.1 1</diffuse>
                        <specular>0.1 0.1 0.1 1</specular>
                    </material>
                    <collision name='collision'>
                        <geometry>
                            <cylinder>
                                <radius>0.4</radius>
                                <length>0.2</length>
                            </cylinder>
                        </geometry>
                    </collision>
                </visual>
            </link>
            <link name='right_rear_wheel'>
                <pose relative_to="chassis">0.88 -0.6 0 -1.5707 0 0</pose>
                <inertial>
                    <mass>1</mass>
                    <inertia>
                        <ixx>0.043333</ixx>
                        <ixy>0</ixy>
                        <ixz>0</ixz>
                        <iyy>0.043333</iyy>
                        <iyz>0</iyz>
                        <izz>0.08</izz>
                    </inertia>
                </inertial>
                <visual name='visual'>
                    <geometry>
                        <cylinder>
                            <radius>0.4</radius>
                            <length>0.2</length>
                        </cylinder>
                    </geometry>
                    <material>
                        <ambient>0.1 0.1 0.1 1</ambient>
                        <diffuse>0.1 0.1 0.1 1</diffuse>
                        <specular>0.1 0.1 0.1 1</specular>
                    </material>
                    <collision name='collision'>
                        <geometry>
                            <cylinder>
                                <radius>0.4</radius>
                                <length>0.2</length>
                            </cylinder>
                        </geometry>
                    </collision>
                </visual>
            </link>

            <joint name='left_front_joint' type='revolute'>
                <pose relative_to='left_front_wheel' />
                <parent>chassis</parent>
                <child>left_front_wheel</child>
                <axis>
                    <xyz expressed_in="__model__">0 1 0</xyz>
                    <limit>
                        <lower>-1.79769e+308</lower>
                        <upper>1.79769e+308</upper>
                    </limit>
                </axis>
            </joint>
            <joint name='left_rear_joint' type='revolute'>
                <pose relative_to='left_rear_wheel' />
                <parent>chassis</parent>
                <child>left_rear_wheel</child>
                <axis>
                    <xyz expressed_in="__model__">0 1 0</xyz>
                    <limit>
                        <lower>-1.79769e+308</lower>
                        <upper>1.79769e+308</upper>
                    </limit>
                </axis>
            </joint>
            <joint name='right_front_joint' type='revolute'>
                <pose relative_to='right_front_wheel' />
                <parent>chassis</parent>
                <child>right_front_wheel</child>
                <axis>
                    <xyz expressed_in="__model__">0 1 0</xyz>
                    <limit>
                        <lower>-1.79769e+308</lower>
                        <upper>1.79769e+308</upper>
                    </limit>
                </axis>
            </joint>
            <joint name='right_rear_joint' type='revolute'>
                <pose relative_to='right_rear_wheel' />
                <parent>chassis</parent>
                <child>right_rear_wheel</child>
                <axis>
                    <xyz expressed_in="__model__">0 1 0</xyz>
                    <limit>
                        <lower>-1.79769e+308</lower>
                        <upper>1.79769e+308</upper>
                    </limit>
                </axis>
            </joint>

            <!-- define camera which will attach to the car body -->
            <frame name="player_camera_frame" attached_to="chassis">
                <pose>0.8 0 -0.2 0 0 0</pose>
            </frame>
            <link name='player_camera'>
                <pose relative_to='player_camera_frame' />
                <inertial>
                    <mass>1</mass>
                    <inertia>
                        <ixx>0.016</ixx>
                        <ixy>0</ixy>
                        <ixz>0</ixz>
                        <iyy>0.016</iyy>
                        <iyz>0</iyz>
                        <izz>0.016</izz>
                    </inertia>
                </inertial>
                <visual name='visual'>
                    <geometry>
                        <sphere>
                            <radius>0.2</radius>
                        </sphere>
                    </geometry>
                    <material>
                        <ambient>0.0 1 0.0 1</ambient>
                        <diffuse>0.0 1 0.0 1</diffuse>
                        <specular>0.0 1 0.0 1</specular>
                    </material>
                </visual>
                <collision name='collision'>
                    <geometry>
                        <sphere>
                            <radius>0.2</radius>
                        </sphere>
                    </geometry>
                </collision>
            </link>
            <joint name='player_camera_wheel' type='ball'>
                <parent>chassis</parent>
                <child>player_camera</child>
            </joint>
        </model>
    </world>
</sdf>